Workbook

Sheet Summary
B2: TASKR Test Case Document
B3: Login Screen · OTP Verification Screen · Dashboard Screen
B5: Prepared by | D5: RIDA KHAN (SQA ENGINEER)
B6: Version | D6: 1.0
B7: Date | D7: 46072
B8: Platform | D8: Web | Chromium | dev.taskr.co.uk
B9: Application | D9: TASKR | Staff Management Platform
B10: Auth State | D10: Logged-out (Login/OTP) · Logged-in (Dashboard)
B12: TEST CASE SUMMARY
B13: Screen | C13: Sheet | D13: P0 Tests | E13: P1 Tests | F13: P2 Tests | G13: Total TCs | H13: Coverage Areas
B14: Login Screen | C14: Login TCs | D14: =COUNTIF(Login!G4:G100,"P0") -> 15 | E14: =COUNTIF(Login!G4:G100,"P1") -> 16 | F14: =COUNTIF(Login!G4:G100,"P2") -> 3 | G14: =COUNTA(Login!A4:A100) -> 34 | H14: 12
B15: OTP Verification | C15: OTP TCs | D15: =COUNTIF('OTP '!G4:G100,"P0") -> 12 | E15: =COUNTIF('OTP '!G4:G100,"P1") -> 13 | F15: =COUNTIF('OTP '!G4:G100,"P2") -> 3 | G15: =COUNTA('OTP '!A4:A100) -> 28 | H15: 11
B16: Dashboard | C16: Dashboard TCs | D16: =COUNTIF('Dashboard '!G4:G100,"P0") -> 8 | E16: =COUNTIF('Dashboard '!G4:G100,"P1") -> 33 | F16: =COUNTIF('Dashboard '!G4:G100,"P2") -> 9 | G16: =COUNTA('Dashboard '!A4:A100) -> 50 | H16: 17
B17: Integration / E2E | C17: Integration TCs | D17: =COUNTIF('Integration '!G4:G100,"P0") -> 3 | E17: =COUNTIF('Integration '!G4:G100,"P1") -> 3 | F17: =COUNTIF('Integration '!G4:G100,"P2") -> 0 | G17: =COUNTA('Integration '!A4:A100) -> 6 | H17: 6
B18: TOTALS | C18: =SUM(C14:C17) -> 0 | D18: =SUM(D14:D17) -> 38 | E18: =SUM(E14:E17) -> 65 | F18: =SUM(F14:F17) -> 15
B20: WORKBOOK SHEETS
B21: Sheet | C21: Description
B22: Summary | C22: This overview sheet metadata, counts, sheet index
B23: Login TCs | C23: 34 test cases covering Login screen (LGN-001 → LGN-034)
B24: OTP TCs | C24: 28 test cases covering OTP Verification screen (OTP-001 → OTP-028)
B25: Dashboard TCs | C25: 50 test cases covering Dashboard screen (DSH-001 → DSH-050)
B26: Integration TCs | C26: 6 cross-screen end-to-end integration tests (E2E-001 → E2E-006)
B27: Coverage Matrix | C27: Functional coverage matrix for all three screens
B28: Risk Register | C28: Top 5 risks per screen with impact, likelihood & mitigation
B29: Release Checklist | C29: Pre-release sanity checklist for all three screens

Sheet Login
A1: LOGIN SCREEN | dev.taskr.co.uk/login
A2: ID | B2: Title | C2: Preconditions | D2: Test Steps | E2: Test Data | F2: Expected Result | G2: Priority | H2: Notes | I2: Automate?
A4: LGN-001 | B4: Happy Path Login | C4: User logged out; valid credentials exist in test env | D4: 1. Open dev.taskr.co.uk/login 2. Enter valid email 3. Enter valid password 4. Click Login | E4: Email: testadmin@taskr.co.uk Password: ValidP@ss1! | F4: Page redirects to /otp?redirect=%2Fapp%2Fdashboard. No JS console errors. HTTP 200 from login API. | G4: P0 | H4: Core smoke test. Run first in every build. | I4: Yes
A5: LGN-002 | B5: Redirect Param Preserved | C5: Logged out; navigate to https://dev.taskr.co.uk/login | D5: 1. Open URL with redirect param 2. Enter valid credentials 3. Click Login 4. Complete OTP | E5: URL: https://dev.taskr.co.uk/login | F5: After successful OTP, user lands on /app/dashboard — the original redirect target. | G5: P0 | H5: Verify redirect param is passed through OTP screen and honoured post-verify. | I5: Yes
A6: LGN-003 | B6: Login with Remember Me Checked | C6: Logged out; browser cookie inspection tools available | D6: 1. Enter valid credentials 2. Check 'Remember me' checkbox 3. Click Login 4. Complete OTP 5. Close all browser tabs 6. Reopen dev.taskr.co.uk | E6: Remember me: ✓ checked | F6: User is still authenticated on reopening. Cookie is persistent (Expires set, not session-scoped). Cookie attributes: Secure, HttpOnly, SameSite=Lax or Strict. | G6: P1 | H6: Inspect Set-Cookie header in DevTools Network tab. | I6: Yes
A7: LGN-004 | B7: Login without Remember Me (default) | C7: Logged out | D7: 1. Enter valid credentials (Remember me unchecked) 2. Login → OTP → Dashboard 3. Close all browser tabs 4. Reopen app URL | E7: Remember me: unchecked (default state) | F7: User is redirected to /login. Session cookie is absent or marked as session-only (no Expires/Max-Age). | G7: P1 | H7: Session cookie should expire when browser session ends. | I7: Yes
A8: LGN-005 | B8: Submit — Empty Email | C8: Logged out | D8: 1. Leave email field blank 2. Enter any password 3. Click Login | E8: Email: (empty) Password: anyValue | F8: Inline error displayed: 'Email address is required' (or similar). Login API not called. User stays on login page. | G8: P0 | H8: Client-side validation. Verify no XHR made. | I8: Yes
A9: LGN-006 | B9: Submit — Empty Password | C9: Logged out | D9: 1. Enter valid email 2. Leave password blank 3. Click Login | E9: Email: valid@email.com Password: (empty) | F9: Inline error: 'Password is required'. Login API not called. | G9: P0 | I9: Yes
A10: LGN-007 | B10: Submit — Both Fields Empty | C10: Logged out | D10: 1. Click Login without filling any field | E10: Email: (empty) Password: (empty) | F10: Both fields show required-field error messages simultaneously. No API call made. | G10: P0 | I10: Yes
A11: LGN-008 | B11: Invalid Email Format | C11: Logged out | D11: 1. Enter malformed email address 2. Enter any password 3. Click Login | E11: Email: notanemail (also test: a@, @b.com, user @domain.com) Password: Any | F11: Inline validation error: 'Please enter a valid email address'. No API call. | G11: P1 | H11: Parameterise with 4 invalid email variants. | I11: Yes
A12: LGN-009 | B12: Wrong Password — Known Account | C12: Logged out; known test account | D12: 1. Enter correct email for known account 2. Enter incorrect password 3. Click Login | E12: Email: testadmin@taskr.co.uk Password: WrongPass99 | F12: Generic error: 'Invalid email or password'. Does NOT reveal which field is wrong. User stays on login. HTTP 401. | G12: P0 | H12: Security: generic message prevents account enumeration. | I12: Yes
A13: LGN-010 | B13: Unknown Email Address | C13: Logged out | D13: 1. Enter unregistered email 2. Enter any password 3. Click Login | E13: Email: unknown@notexist.com Password: anyPass | F13: Same generic error as LGN-009. Response time should not differ measurably from wrong-password case (anti-timing-attack). | G13: P0 | H13: Security: no account enumeration via different errors or response times. | I13: Yes
A14: LGN-011 | B14: Brute-Force Lockout | C14: Rate-limit / lockout testing env | D14: 1. Enter valid email 2. Enter wrong password 3. Click Login — repeat 5+ times rapidly | E14: 5+ failed attempts with valid email | F14: After N failures (agreed threshold), account locked or CAPTCHA presented. Error: 'Too many attempts, please try again in X minutes.' HTTP 429. | G14: P0 | H14: Confirm lockout threshold with backend team. Check Retry-After header. | I14: Yes
A15: LGN-012 | B15: Max-Length Email (254 chars) | C15: Logged out | D15: 1. Paste 254-character valid-format email into email field 2. Enter password 3. Click Login | E15: Email: a[×249]@b.com (254 chars total) Password: any | F15: Field accepts input without truncation or crash. Server returns expected error (user not found) gracefully. | G15: P2 | H15: RFC 5321 max email length boundary test. | I15: No
A16: LGN-013 | B16: Email with Leading/Trailing Whitespace | C16: Logged out | D16: 1. Type ' testadmin@taskr.co.uk ' with spaces 2. Enter valid password 3. Click Login | E16: Email: ' testadmin@taskr.co.uk ' (with surrounding spaces) | F16: App trims whitespace and authenticates successfully OR shows clear validation error. Does NOT silently fail. | G16: P1 | H16: Regression risk if backend does strict matching. | I16: No
A17: LGN-014 | B17: SQL Injection in Email Field | C17: Logged out | D17: 1. Enter SQL payload in email field 2. Enter any password 3. Click Login | E17: Email: ' OR '1'='1 Also test: admin'-- Password: anything | F17: Login fails with standard invalid-credentials error. No DB error message exposed. Response time normal. HTTP 401. | G17: P0 | H17: Security. No stack trace, no DB error text in response. | I17: Yes
A18: LGN-015 | B18: XSS Payload in Password Field | C18: Logged out | D18: 1. Enter valid email 2. Enter XSS payload as password 3. Click Login | E18: Password: <script>alert(1)</script> | F18: Error message shown as plain text. No script tag executes. No reflected XSS in any response. | G18: P0 | H18: Security. Check response body and error message rendering. | I18: Yes
A19: LGN-016 | B19: Unicode / Emoji in Password | C19: Account created with unicode password | D19: 1. Enter email 2. Enter unicode/emoji password 3. Click Login | E19: Password: Pässw0rd🔒 | F19: Login succeeds if password matches; generic error if not. No character encoding exception or server crash. | G19: P1 | H19: i18n / encoding robustness. | I19: No
A20: LGN-017 | B20: Password Visibility Toggle — Show | C20: Logged out | D20: 1. Type password into password field 2. Click eye icon once | E20: Password: MySecret123 | F20: Field type changes from 'password' to 'text'. Characters become visible. Eye icon state changes to 'hide'. aria-label updates to 'Hide password'. | G20: P1 | H20: WCAG: aria-label must update to reflect new state. | I20: Yes
A21: LGN-018 | B21: Password Visibility Toggle — Hide | C21: Logged out | D21: 1. Type password 2. Click eye icon to show 3. Click eye icon again to hide | E21: Password: MySecret123 | F21: Field type returns to 'password'. Characters masked again. Icon reverts to 'show' state. | G21: P1 | I21: Yes
A22: LGN-019 | B22: Tab Order and Keyboard Navigation | C22: Logged out | D22: 1. Load login page 2. Press Tab repeatedly to move through all interactive elements 3. Note focus sequence | E22: Keyboard only — no mouse | F22: Focus order: Email input → Password input → Remember Me checkbox → Login button → Forgot password link (or matching DOM order). Focus ring visible on each element. | G22: P1 | H22: WCAG 2.1 SC 2.4.3 Focus Order. | I22: No
A23: LGN-020 | B23: Screen Reader Labels | C23: NVDA or VoiceOver available | D23: 1. Navigate to login with screen reader active 2. Read all interactive elements | E23: Screen reader enabled (NVDA on Chrome or VoiceOver on Safari) | F23: Email field announced: 'Email address, required, edit field'. Password: 'Password, required'. Error messages announced via aria-live region. Remember Me announced as checkbox with state. | G23: P1 | H23: WCAG 1.3.1, 4.1.3. | I23: No
A24: LGN-021 | B24: Colour Contrast — Labels & Placeholders | C24: axe DevTools or browser inspector | D24: 1. Install axe DevTools 2. Run scan on login page 3. Review contrast results | E24: N/A | F24: All text passes WCAG AA contrast ratios: 4.5:1 for normal text, 3:1 for large text. Red asterisk (*) not the sole error indicator. | G24: P1 | H24: WCAG 1.4.3. | I24: No
A25: LGN-022 | B25: HTTPS Enforced | C25: HTTP URL attempted | D25: 1. Navigate to http://dev.taskr.co.uk/login (HTTP) | E25: HTTP URL | F25: Server/browser redirects to HTTPS automatically. No credentials ever transmitted over plain HTTP. | G25: P0 | H25: Security — transport layer. | I25: Yes
A26: LGN-023 | B26: CSRF Token Present | C26: Browser DevTools / Burp Suite proxy | D26: 1. Log in normally 2. Inspect POST request to /api/auth/login in Network tab 3. Attempt to replay request without CSRF token | E26: Captured POST request | F26: Request contains anti-CSRF token in header or body. Replaying without token returns HTTP 403. | G26: P0 | H26: Security. | I26: Yes
A27: LGN-024 | B27: No Credentials in URL | C27: Logged out | D27: 1. Enter credentials 2. Click Login 3. Inspect browser URL bar and Network tab | E27: Valid credentials | F27: Credentials sent via POST body only. Password never appears in URL, query string, browser history, or network log URL field. | G27: P0 | H27: Security. | I27: Yes
A28: LGN-025 | B28: Page Load Performance | C28: Clean browser cache | D28: 1. Clear cache and cookies 2. Open login page with DevTools Performance tab 3. Record load metrics | E28: Throttled to Fast 3G in DevTools | F28: Page fully interactive < 5 s on 3G. LCP < 2.5 s on desktop unthrottled. CLS < 0.1. No render-blocking scripts. | G28: P2 | H28: Use Lighthouse for automated measurement. | I28: No
A29: LGN-026 | B29: Login Button Loading State | C29: Logged out | D29: 1. Enter valid credentials 2. Click Login 3. Observe button immediately after click | E29: Valid credentials | F29: Button enters disabled/loading state (spinner visible) immediately. Prevents double-submit. Re-enables only on response. | G29: P1 | H29: UX / race condition prevention. | I29: Yes
A30: LGN-027 | B30: Server 500 Error on Login | C30: API mocked to return 500 | D30: 1. Configure mock server to return 500 2. Enter valid credentials 3. Click Login | E30: POST /api/auth/login → HTTP 500 | F30: User-friendly error shown: 'Something went wrong, please try again.' App does not crash. No stack trace exposed to user. | G30: P0 | H30: Error handling. Use Playwright page.route() to mock. | I30: Yes
A31: LGN-028 | B31: Network Timeout | C31: DevTools offline simulation | D31: 1. Enter valid credentials 2. Click Login 3. Immediately set DevTools to 'Offline' | E31: Simulated offline / timeout | F31: Timeout error shown: 'Network error, please check your connection.' App does not hang indefinitely. Button re-enables. | G31: P1 | H31: Error handling. | I31: Yes
A32: LGN-029 | B32: Forgot Password Link — Navigation | C32: Logged out | D32: 1. Click 'Forgot password?' link | E32: N/A | F32: User navigated to password-reset screen. URL changes to /forgot-password or equivalent. | G32: P1 | I32: Yes
A33: LGN-030 | B33: Forgot Password — Keyboard Access | C33: Logged out | D33: 1. Tab to 'Forgot password?' link 2. Press Enter | E33: Keyboard only | F33: Same navigation result as mouse click. Link is focusable and activatable via keyboard. | G33: P1 | H33: WCAG 2.1.1. | I33: No
A34: LGN-031 | B34: Open Redirect Prevention | C34: Logged out | D34: 1. Manually edit URL to: /login?redirect=https://evil.com 2. Enter valid credentials 3. Complete login | E34: redirect param: https://evil.com (external domain) | F34: App does NOT redirect to external domain after login. Redirects to /app/dashboard or shows error. HTTP 400 on malicious redirect. | G34: P0 | H34: Security — open redirect prevention. | I34: Yes
A35: LGN-032 | B35: Already-Authenticated User Visits Login | C35: Valid active session | D35: 1. While authenticated, navigate directly to /login | E35: Valid session cookie present | F35: App redirects authenticated user to /app/dashboard without showing login form. | G35: P1 | H35: Session handling — auth guard. | I35: Yes
A36: LGN-033 | B36: Responsive Layout — Narrow Viewport | C36: Logged out | D36: 1. Resize browser to 375 px wide (iPhone SE) 2. Inspect login form layout | E36: Viewport width: 375 px | F36: All form elements visible and usable. Promo panel may be hidden on mobile. No horizontal scroll. Input fields full-width and easily tappable. | G36: P2 | H36: Responsive design. | I36: No
A37: LGN-034 | B37: Malformed JSON Server Response | C37: API mock returns invalid JSON | D37: 1. Configure mock to return 200 with body: 'not valid json' 2. Enter credentials 3. Click Login | E37: API response: 200 OK, body = 'not json' | F37: App shows generic error message. Does not throw unhandled exception or blank screen. Graceful JSON parse failure handling. | G37: P1 | H37: Resilience / error handling. | I37: Yes

Sheet OTP 
A1: OTP VERIFICATION | dev.taskr.co.uk/otp
A2: ID | B2: Title | C2: Preconditions | D2: Test Steps | E2: Test Data | F2: Expected Result | G2: Priority | H2: Notes | I2: Automate?
A4: OTP-001 | B4: Happy Path — Correct OTP | C4: Login completed on Login screen; OTP received in email inbox | D4: 1. Complete login step 2. Navigate to /otp screen 3. Retrieve 4-digit OTP from email 4. Enter OTP in field 5. Click Verify | E4: OTP: valid 4-digit code from email | F4: User redirected to /app/dashboard. Session fully established. HTTP 200 from /api/auth/verify-otp. | G4: P0 | H4: Core smoke test. Automate with Mailhog/Mailpit email interception in test env. | I4: Yes
A5: OTP-002 | B5: Redirect Param Honoured After OTP | C5: Login with redirect param; OTP screen loaded | D5: 1. Enter correct OTP 2. Click Verify | E5: OTP: valid; URL: https://dev.taskr.co.uk/otp | F5: User lands on /app/dashboard (original redirect target), not app root. | G5: P0 | I5: Yes
A6: OTP-003 | B6: Submit — Empty OTP Field | C6: OTP screen loaded | D6: 1. Leave OTP field empty 2. Click Verify | E6: OTP: (empty) | F6: Inline error: 'Please enter the OTP'. Verify API not called. User stays on OTP screen. | G6: P0 | H6: Client-side validation. | I6: Yes
A7: OTP-004 | B7: Non-Numeric Characters in OTP | C7: OTP screen loaded | D7: 1. Type letters/symbols into OTP field 2. Click Verify | E7: OTP: abcd / !@#$ / AB12 | F7: Field rejects non-numeric input (pattern attribute or JS filter) OR validation error shown: 'OTP must be 4 digits'. API not called. | G7: P1 | H7: type=tel or inputmode=numeric should restrict on mobile; test desktop too. | I7: Yes
A8: OTP-005 | B8: OTP Too Short (< 4 digits) | C8: OTP screen loaded | D8: 1. Enter 1–3 digit value 2. Click Verify | E8: OTP: 1 / 12 / 123 | F8: Validation error: 'OTP must be 4 digits'. Verify API not called. | G8: P1 | H8: Client-side maxlength or length check. | I8: Yes
A9: OTP-006 | B9: OTP Too Long (> 4 digits) | C9: OTP screen loaded | D9: 1. Attempt to type 5 or more digits | E9: OTP: 12345 (5 digits) | F9: Field caps at 4 characters (maxlength=4). 5th character not accepted OR error shown on submit. | G9: P1 | I9: Yes
A10: OTP-007 | B10: Wrong OTP — Incorrect Code | C10: OTP screen loaded | D10: 1. Enter incorrect 4-digit OTP 2. Click Verify | E10: OTP: 0000 (known incorrect) | F10: Error: 'Invalid OTP. Please try again.' User stays on OTP screen. Attempt counter increments server-side. HTTP 401. | G10: P0 | I10: Yes
A11: OTP-008 | B11: Expired OTP | C11: OTP received; wait past expiry window (e.g., 5 min) | D11: 1. Receive OTP 2. Wait for expiry period to pass 3. Enter expired OTP 4. Click Verify | E11: OTP: original code entered after expiry | F11: Error: 'OTP has expired. Please request a new code.' Resend option highlighted/offered. | G11: P0 | H11: Use test-env flag or time manipulation to set OTP expiry to 0 in CI. | I11: Yes
A12: OTP-009 | B12: Resend Disabled During Countdown | C12: OTP screen loaded; timer active | D12: 1. Observe 'Resend' control while countdown is > 0 seconds 2. Attempt to click/activate resend | E12: Timer: > 0 seconds | F12: Resend button/link is visually disabled (greyed out) and not clickable while countdown > 0. | G12: P1 | I12: Yes
A13: OTP-010 | B13: Resend Enabled After Countdown Reaches 0 | C13: OTP screen loaded | D13: 1. Wait for countdown timer to reach 0 2. Observe resend control | E13: Timer: reaches 0 seconds | F13: Resend button/link becomes active (enabled, clickable). UI updates immediately at 0. | G13: P1 | H13: Use Playwright fake timers to advance time deterministically. | I13: Yes
A14: OTP-011 | B14: Resend Generates New OTP | C14: Countdown reached 0 | D14: 1. Click Resend 2. Check email inbox | E14: Resend clicked | F14: New OTP received in email. New countdown timer restarts from ~60 s. API called: POST /api/auth/resend-otp. | G14: P0 | I14: Yes
A15: OTP-012 | B15: Old OTP Invalid After Resend | C15: New OTP sent via resend | D15: 1. Note first OTP received 2. Click Resend (new OTP sent) 3. Enter original first OTP 4. Click Verify | E15: OTP: first/original code (now superseded) | F15: Error: 'Invalid OTP'. Only most recently issued OTP is accepted. Previous OTP invalidated server-side. | G15: P0 | H15: Security — prevents OTP accumulation attacks. | I15: Yes
A16: OTP-013 | B16: Multiple Rapid Resend Attempts | C16: Countdown at 0 | D16: 1. Click Resend 5+ times in quick succession | E16: Rapid resend clicks | F16: Rate limiting applied after N resends. Further resend blocked: 'Too many requests, please wait.' HTTP 429. | G16: P1 | H16: Security / abuse prevention. | I16: Yes
A17: OTP-014 | B17: Max Wrong OTP Retries → Lockout | C17: Known incorrect OTP | D17: 1. Enter wrong OTP 2. Click Verify 3. Repeat steps 1-2 five or more times | E17: OTP: 0000 (wrong) × 5+ | F17: After N failures, user locked out: redirected to /login with message 'Too many failed attempts. Please log in again.' Partial session invalidated. | G17: P0 | H17: Confirm threshold N with backend spec. Critical security control. | I17: Yes
A18: OTP-015 | B18: Sign In with Different Email | C18: OTP screen active | D18: 1. Click 'Sign in with different email address' button | E18: N/A | F18: User redirected to /login. Partial auth state cleared server-side. No auto-fill of previous email. | G18: P1 | H18: Verify partial session token invalidated server-side. | I18: Yes
A19: OTP-016 | B19: Direct Navigation to /otp Without Login | C19: No prior login step; logged out | D19: 1. Clear cookies 2. Navigate directly to dev.taskr.co.uk/otp | E19: No prior login; no partial session | F19: User redirected to /login. OTP screen not accessible without completing credential step. | G19: P0 | H19: Security — authentication flow bypass prevention. | I19: Yes
A20: OTP-017 | B20: OTP Not Exposed in URL or Logs | C20: OTP screen active | D20: 1. Monitor URL bar and DevTools Network during verification 2. Check console logs | E20: DevTools open | F20: OTP value sent in POST body only. Never in URL, query string, browser address bar, or console output. | G20: P0 | H20: Security. | I20: Yes
A21: OTP-018 | B21: Replay Attack — Reuse of Already-Used OTP | C21: OTP previously verified successfully | D21: 1. Use valid OTP to log in 2. Log out 3. Initiate new login 4. On OTP screen, enter the previously used OTP | E21: OTP: previously verified code | F21: Second use rejected: 'Invalid or already used OTP.' OTP is single-use, enforced server-side. | G21: P0 | H21: Security — single-use enforcement. | I21: Yes
A22: OTP-019 | B22: Timer Accuracy | C22: OTP screen loaded | D22: 1. Load OTP screen 2. Use external stopwatch to time the countdown | E22: External stopwatch comparison | F22: Client timer counts down accurately within ±1 second per 60 s. Does not drift or skip. | G22: P2 | H22: UX. Timer is cosmetic; server-side expiry is authoritative. | I22: No
A23: OTP-020 | B23: Tab Order and Keyboard Navigation | C23: OTP screen loaded | D23: 1. Use Tab key to navigate all interactive elements on OTP screen | E23: Keyboard only | F23: Tab order: OTP input → Verify button → 'Sign in with different email'. Focus ring visible on each. All elements reachable. | G23: P1 | H23: WCAG 2.4.3. | I23: No
A24: OTP-021 | B24: Screen Reader — Timer Countdown Announcements | C24: NVDA / VoiceOver | D24: 1. Load OTP screen with screen reader 2. Listen for timer update announcements | E24: Screen reader active | F24: Timer uses aria-live='polite'. Not announced every second (too noisy). Announced at key intervals (e.g., when resend activates at 0 s). | G24: P1 | H24: WCAG 4.1.3 Status Messages. | I24: No
A25: OTP-022 | B25: Screen Reader — Error Message Announcement | C25: NVDA / VoiceOver | D25: 1. Submit empty OTP field 2. Listen for error announcement with screen reader | E25: Screen reader active | F25: Error message immediately announced via aria-live='assertive' or focus moved programmatically to error. | G25: P1 | H25: WCAG 1.3.1. | I25: No
A26: OTP-023 | B26: Colour Contrast — OTP Screen | C26: axe DevTools | D26: 1. Run axe scan on OTP screen 2. Trigger validation error 3. Re-run scan | E26: N/A | F26: All text and error messages meet WCAG AA contrast ratios (4.5:1 normal, 3:1 large). Error state meets same ratios. | G26: P1 | I26: No
A27: OTP-024 | B27: Server 500 on Verify | C27: API mocked to return 500 | D27: 1. Configure mock: POST /api/auth/verify-otp → 500 2. Enter valid OTP 3. Click Verify | E27: API: HTTP 500 | F27: User-friendly error: 'Something went wrong. Please try again.' App does not crash. Verify button re-enables. | G27: P0 | H27: Error handling. Use Playwright page.route(). | I27: Yes
A28: OTP-025 | B28: Network Timeout on Verify | C28: DevTools offline | D28: 1. Enter valid OTP 2. Click Verify 3. Immediately set DevTools to Offline | E28: Simulated network offline | F28: Timeout error shown: 'Network error.' Button returns to active state. User can retry. | G28: P1 | I28: Yes
A29: OTP-026 | B29: Verify Button Loading State | C29: OTP screen loaded | D29: 1. Enter valid OTP 2. Click Verify 3. Observe button state immediately | E29: Valid OTP | F29: Button enters disabled/loading state immediately, preventing double-submit. Re-enables on response. | G29: P1 | I29: Yes
A30: OTP-027 | B30: Paste OTP from Clipboard | C30: OTP received in email | D30: 1. Copy OTP from email 2. Click OTP field 3. Paste (Ctrl+V / Cmd+V) | E30: Clipboard: '1234' | F30: OTP pasted successfully into field. No content stripping. Single-paste workflow works. | G30: P2 | H30: Common real-user behaviour. Blocking paste is a UX anti-pattern. | I30: No
A31: OTP-028 | B31: Numeric Keyboard on Mobile | C31: Mobile browser or DevTools mobile emulation | D31: 1. Open OTP screen on mobile viewport 2. Tap OTP input field | E31: Mobile viewport (375 px) | F31: Numeric keypad appears on mobile (inputmode='numeric' or type='tel'). Easier OTP entry. | G31: P2 | H31: Mobile UX. | I31: No

Sheet Dashboard 
A1: DASHBOARD | dev.taskr.co.uk/app/dashboard
A2: ID | B2: Title | C2: Preconditions | D2: Test Steps | E2: Test Data | F2: Expected Result | G2: Priority | H2: Notes | I2: Automate?
A4: DSH-001 | B4: Dashboard Loads for Authenticated User | C4: User fully logged in (post-OTP); valid session | D4: 1. Navigate to /app/dashboard | E4: Valid session cookie | F4: Page loads successfully. All 5 widget sections visible: Scheduled Health, Leave Request, Important Events, Schedule Overview, Compliance Overview. No console errors. | G4: P0 | H4: Core smoke test. Automate. | I4: Yes
A5: DSH-002 | B5: Unauthenticated Access Redirected to Login | C5: No active session; all cookies cleared | D5: 1. Clear all cookies 2. Navigate directly to /app/dashboard | E5: No auth cookie | F5: User redirected to /login?redirect=%2Fapp%2Fdashboard. Dashboard content not shown. HTTP 401 or 302. | G5: P0 | H5: Security — auth gate. | I5: Yes
A6: DSH-003 | B6: Expired Session Mid-Use Redirected | C6: Session expires while actively on dashboard | D6: 1. Login, reach dashboard 2. Expire session (delete cookie or use API) 3. Click any widget action button | E6: Session expired | F6: User redirected to /login. No sensitive data displayed after expiry. Appropriate error/notification shown. | G6: P0 | H6: Security. | I6: Yes
A7: DSH-004 | B7: Scheduled Health — Default 7D View | C7: Logged in | D7: 1. Observe Scheduled Health widget immediately after page load | E7: Default state | F7: Widget shows donut chart with Allocated, Warning, Unallocated segments and legend. Total number (e.g., 37) displayed. 7D tab active by default. | G7: P1 | H7: Verify default tab from screenshot context. | I7: Yes
A8: DSH-005 | B8: Scheduled Health — Switch to 12hr Tab | C8: Dashboard loaded | D8: 1. Click '12hr' tab on Scheduled Health widget | E8: Click: 12hr tab | F8: Widget data updates to last 12-hour window. Donut chart re-renders with new counts. Active tab highlighted with visual indicator. | G8: P1 | I8: Yes
A9: DSH-006 | B9: Scheduled Health — Switch to 28D Tab | C9: Dashboard loaded | D9: 1. Click '28D' tab on Scheduled Health widget | E9: Click: 28D tab | F9: Widget data updates to 28-day range. Chart and totals update. Active tab styling applied to 28D. | G9: P1 | I9: Yes
A10: DSH-007 | B10: Scheduled Health — Zero / Empty State | C10: Test data: all staff allocated, 0 warnings/unallocated | D10: 1. Load dashboard with zero-state test data set | E10: Test env: Allocated=37, Warning=0, Unallocated=0 | F10: Widget displays correctly with 0 values. No division-by-zero JS error. Donut chart renders gracefully (100% one colour or empty state). | G10: P2 | H10: Edge case — data boundary. | I10: No
A11: DSH-008 | B11: Scheduled Health — Widget API Error | C11: Widget API mocked to return 500 | D11: 1. Mock GET /api/dashboard/scheduled-health → 500 2. Load dashboard | E11: API: HTTP 500 | F11: Scheduled Health widget shows error state: 'Unable to load data. Retry.' or similar. Other widgets load independently and unaffected. | G11: P1 | H11: Error isolation. Use Playwright page.route(). | I11: Yes
A12: DSH-009 | B12: Leave Request — Data Renders Correctly | C12: Leave request data exists in test env (e.g., 4 requests) | D12: 1. Load dashboard 2. Observe Leave Request widget | E12: Test data: 4 leave requests (28+ days band) | F12: Total count '4' displayed. Bar chart shows orange bar in '28+ days' band matching test data. Legend visible with correct colour coding. | G12: P1 | I12: Yes
A13: DSH-010 | B13: Leave Request — Zero State | C13: No pending leave requests in test env | D13: 1. Load dashboard with zero leave data | E13: Test data: 0 leave requests | F13: Widget shows '0' total. Chart shows empty state or 'No leave requests' placeholder. No rendering error. | G13: P2 | I13: No
A14: DSH-011 | B14: Leave Request — 'View All' Navigation | C14: Dashboard loaded | D14: 1. Click 'view all' link on Leave Request widget | E14: Click: view all | F14: User navigated to full leave management screen. URL changes to expected leave-list route. | G14: P1 | I14: Yes
A15: DSH-012 | B15: Leave Request — Widget API Error | C15: Widget API mocked to 500 | D15: 1. Mock leave request API → 500 2. Load dashboard | E15: API: HTTP 500 | F15: Leave widget shows error state. All other widgets load normally. No full-page crash. | G15: P1 | I15: Yes
A16: DSH-013 | B16: Important Events — Zero State | C16: No events in test env | D16: 1. Load dashboard with no events | E16: Events: 0 | F16: Widget shows '0' badge and text 'No important events'. Layout intact. 'view all' link still present. | G16: P1 | H16: Matches current screenshot state. | I16: Yes
A17: DSH-014 | B17: Important Events — With Events | C17: Events exist in test env | D17: 1. Load dashboard with event data (e.g., 3 events) | E17: Events: 3 in test data | F17: Badge count shows '3'. Events listed or summarised. 'view all' link active. | G17: P1 | I17: Yes
A18: DSH-015 | B18: Important Events — 'View All' Navigation | C18: Dashboard loaded | D18: 1. Click 'view all' on Important Events widget | E18: Click: view all | F18: User navigated to events screen. URL changes to expected events route. | G18: P1 | I18: Yes
A19: DSH-016 | B19: Schedule Overview — Default Week Displayed | C19: Logged in | D19: 1. Load dashboard 2. Observe Schedule Overview table | E19: Current ISO week (e.g., 19 Apr – 25 Apr) | F19: Current week shown with correct date range label. Columns: Sun, Mon, Tue, Wed, Thu, Fri, Sat. Region rows populated with X/Y values. | G19: P0 | H19: Core functional test. | I19: Yes
A20: DSH-017 | B20: Schedule Overview — Navigate to Previous Week | C20: Dashboard loaded | D20: 1. Click '<' (previous week) arrow on Schedule Overview | E20: Click: < arrow | F20: Date range shifts back 7 days. Columns relabelled with previous week dates. Data updates for that week. | G20: P1 | I20: Yes
A21: DSH-018 | B21: Schedule Overview — Navigate to Next Week | C21: Dashboard loaded | D21: 1. Click '>' (next week) arrow | E21: Click: > arrow | F21: Date range advances 7 days. Data loads for future week (may show 0/0 if unscheduled). No error on future dates. | G21: P1 | I21: Yes
A22: DSH-019 | B22: Schedule Overview — 28D View Toggle | C22: Dashboard loaded | D22: 1. Click '28D' toggle on Schedule Overview section | E22: Click: 28D toggle | F22: View switches to 28-day layout. More columns or aggregated daily view shown. Navigation arrows still functional. | G22: P1 | I22: Yes
A23: DSH-020 | B23: Schedule Overview — Colour Coding Thresholds | C23: Test data with mixed allocation states | D23: 1. Load dashboard with test week having: - East: 1/2 (yellow) - Test North Region: 0/2 (red) - South: 1/1 (green) | E23: Test data: specific region allocation values | F23: Green cells: fully allocated (X/Y where X=Y, X>0). Yellow cells: partially allocated (0<X<Y). Red cells: 0 allocated. Cell colours match these rules. | G23: P0 | H23: Core usability — colour coding is a primary UI signal. | I23: Yes
A24: DSH-021 | B24: Schedule Overview — 0/0 Cell Display | C24: Region with no shifts scheduled for week | D24: 1. Load dashboard with region having 0/0 allocation | E24: Test data: region with no shifts | F24: Cell displays '0/0' without error. No division-by-zero JS exception. Cell shown as neutral/grey (no red/yellow/green override). | G24: P2 | H24: Edge case — boundary data. | I24: No
A25: DSH-022 | B25: Schedule Overview — Fullscreen Toggle | C25: Dashboard loaded | D25: 1. Click fullscreen icon on Schedule Overview widget | E25: Click: fullscreen icon | F25: Schedule table expands to fill viewport. All columns and rows visible/scrollable. Esc key or close button exits fullscreen. | G25: P2 | I25: No
A26: DSH-023 | B26: Compliance Overview — Default State | C26: Compliance data exists (1 warning in test env) | D26: 1. Load dashboard 2. Observe Compliance Overview table | E26: Test data: 1 warning — Key Holding expiring in 88 days | F26: Table shows: Emp. ID, Officer name, Role, Type, Site, Warning badge. '1 Warnings' badge visible. Site filter shows 'All'. 20D tab active. | G26: P0 | H26: Core compliance feature. | I26: Yes
A27: DSH-024 | B27: Compliance Overview — Site Filter | C27: Multiple sites in test env | D27: 1. Click Site dropdown on Compliance Overview 2. Select a specific site (e.g., 'Rafay site') | E27: Site: 'Rafay site' | F27: Table filters to show only officers from selected site. Row count and warnings badge count update accordingly. | G27: P1 | I27: Yes
A28: DSH-025 | B28: Compliance Overview — Reset Site Filter to All | C28: Site filter active | D28: 1. With specific site selected 2. Select 'All' from site dropdown | E28: Site: All | F28: All compliance records shown again. Badge count reflects total across all sites. | G28: P1 | I28: Yes
A29: DSH-026 | B29: Compliance Overview — 60D Tab | C29: Dashboard loaded | D29: 1. Click '60D' tab on Compliance Overview | E29: Click: 60D tab | F29: Data updates to show compliance warnings within 60-day window. Table rows may increase. 60D tab highlighted as active. | G29: P1 | I29: Yes
A30: DSH-027 | B30: Compliance Overview — 90D Tab | C30: Dashboard loaded | D30: 1. Click '90D' tab on Compliance Overview | E30: Click: 90D tab | F30: Data updates for 90-day compliance window. All warnings within 90 days shown. | G30: P1 | I30: Yes
A31: DSH-028 | B31: Compliance Warning Badge — Content and Readability | C31: Warning badge visible | D31: 1. Observe warning badge on compliance row 2. Check for full text visibility 3. Test hover/tooltip if present | E31: Badge: 'Key Holding is expiring in 88 days' | F31: Warning badge text is fully readable. Colour contrast meets WCAG AA. Full text visible or accessible via tooltip. Text not critically truncated. | G31: P1 | I31: No
A32: DSH-029 | B32: Compliance Overview — No Warnings State | C32: Test data with zero compliance warnings | D32: 1. Load dashboard with clean compliance data (no warnings) | E32: Test data: no warnings | F32: No badge or badge shows '0 Warnings'. Table shows placeholder text or is empty. No layout break. | G32: P2 | I32: No
A33: DSH-030 | B33: Compliance Overview — Fullscreen Toggle | C33: Dashboard loaded | D33: 1. Click fullscreen icon on Compliance Overview widget | E33: Click: fullscreen icon | F33: Compliance table expands to full viewport. Sortable columns still functional. Esc / close button exits. | G33: P2 | I33: No
A34: DSH-031 | B34: Shift Monitoring CTA — Navigation | C34: Logged in | D34: 1. Click 'Shift monitoring' button (top-right) | E34: Click: Shift monitoring button | F34: User navigated to Shift Monitoring screen. URL updates to expected route. Button count/badge visible if applicable. | G34: P1 | I34: Yes
A35: DSH-032 | B35: Manage Sites CTA — Navigation | C35: Logged in | D35: 1. Click 'Manage sites' button (top-right) | E35: Click: Manage sites button | F35: User navigated to Manage Sites screen. URL updates. | G35: P1 | I35: Yes
A36: DSH-033 | B36: CTA Buttons — Keyboard Access | C36: Dashboard loaded | D36: 1. Tab to 'Shift monitoring' button 2. Press Enter 3. Navigate back 4. Tab to 'Manage sites' 5. Press Enter | E36: Keyboard only | F36: Both CTA buttons reachable via Tab. Activated via Enter key. Visible focus ring on each. | G36: P1 | H36: WCAG 2.1.1. | I36: No
A37: DSH-034 | B37: Sidebar — Home Icon Active State | C37: Dashboard loaded | D37: 1. Observe sidebar navigation on dashboard | E37: N/A | F37: Home icon is visually highlighted/active (different colour or indicator) since user is on dashboard. | G37: P1 | I37: Yes
A38: DSH-035 | B38: Sidebar — Staff Icon Navigation | C38: Dashboard loaded | D38: 1. Click staff/people icon in sidebar | E38: Click: staff icon | F38: User navigated to staff management screen. URL changes. Staff icon becomes active. | G38: P1 | I38: Yes
A39: DSH-036 | B39: Sidebar — Calendar Icon Navigation | C39: Dashboard loaded | D39: 1. Click calendar icon in sidebar | E39: Click: calendar icon | F39: User navigated to schedule/calendar screen. URL changes. | G39: P1 | I39: Yes
A40: DSH-037 | B40: Sidebar — Keyboard Navigation | C40: Dashboard loaded | D40: 1. Tab through all sidebar navigation icons 2. Verify each is focusable and activatable | E40: Keyboard only | F40: All sidebar icons reachable via Tab. Focus rings visible. Screen reader announces meaningful labels for each icon (not just 'button'). | G40: P1 | H40: WCAG 2.4.3, 1.1.1 for icon alt text. | I40: No
A41: DSH-038 | B41: Settings Icon — Navigation | C41: Dashboard loaded | D41: 1. Click settings gear icon (bottom-left of sidebar) | E41: Click: settings icon | F41: User navigated to settings screen or settings panel opens. URL/state changes. | G41: P2 | I41: No
...

Sheet Integration 
A1: CROSS-SCREEN INTEGRATION TESTS | dev.taskr.co.uk — Full Flow
A2: ID | B2: Title | C2: Preconditions | D2: Test Steps | E2: Test Data | F2: Expected Result | G2: Priority | H2: Notes | I2: Automate?
A4: E2E-001 | B4: Full Login → OTP → Dashboard Flow | C4: Clean environment; valid test account; Mailhog running | D4: 1. Open /login 2. Enter valid email + password 3. Click Login 4. Retrieve OTP from Mailhog API 5. Enter OTP on /otp screen 6. Click Verify 7. Verify landing page | E4: Email: testadmin@taskr.co.uk Password: ValidP@ss1! OTP: retrieved from Mailhog | F4: User successfully lands on /app/dashboard with all widgets loaded. Full session established. 0 console errors throughout. | G4: P0 | H4: Primary E2E smoke test. Run on every CI build and every deploy to staging. | I4: Yes
A5: E2E-002 | B5: Remember Me — Session Persists Across Browser Close | C5: Logged out | D5: 1. Login with 'Remember me' checked 2. Complete OTP 3. Reach dashboard 4. Close all browser windows 5. Reopen browser and navigate to /app/dashboard | E5: Remember me: checked | F5: User is still authenticated after browser reopen. Dashboard loads without re-login. Persistent cookie present with correct attributes. | G5: P1 | H5: Cross-session persistence test. | I5: Yes
A6: E2E-003 | B6: Session Expiry Mid-Dashboard → Re-Login → Return to Dashboard | C6: Valid session that will be expired | D6: 1. Login, reach dashboard 2. Force session expiry (delete auth cookie or use test API endpoint) 3. Click any interactive element on dashboard (e.g., widget CTA) 4. On login page: re-enter credentials + OTP 5. Verify landing | E6: Session forcibly expired mid-session | F6: On step 3: redirected to /login?redirect=%2Fapp%2Fdashboard. After re-login + OTP: user returned to /app/dashboard. No data leakage in redirect. | G6: P0 | H6: Session lifecycle / expiry handling. | I6: Yes
A7: E2E-004 | B7: Sign In with Different Email — Isolates Sessions | C7: Two valid test accounts: User A and User B | D7: 1. Login as User A 2. On OTP screen, click 'Sign in with different email' 3. Login as User B 4. Complete OTP for User B 5. Verify dashboard shows User B's data | E7: Account A: manager_a@taskr.co.uk Account B: manager_b@taskr.co.uk | F7: Dashboard shows User B's data, not User A's. No data leakage between sessions. User A's partial session fully invalidated server-side. | G7: P1 | H7: Cross-account session isolation. | I7: Yes
A8: E2E-005 | B8: Role-Based Access — Manager vs Officer Dashboard | C8: Manager account + Officer account in test env | D8: 1. Login as Manager role → reach dashboard → note widgets visible 2. Logout 3. Login as Officer role → reach dashboard → note widgets visible | E8: Manager: manager@taskr.co.uk Officer: officer@taskr.co.uk | F8: Manager sees full dashboard with all widgets including Compliance. Officer sees restricted view — no unauthorized data widgets. Both users reach their respective dashboards successfully. | G8: P0 | H8: RBAC integration — security + functionality. | I8: Yes
A9: E2E-006 | B9: Forgot Password → Return to Login → Full Auth Flow | C9: Logged out | D9: 1. Click 'Forgot password?' on login 2. Complete password reset flow 3. Return to /login 4. Login with new password 5. Complete OTP 6. Verify dashboard loads | E9: Account with known email; new password chosen during reset | F9: Full flow completes end-to-end. User can authenticate with new password. Dashboard loads with correct data. Old password rejected on subsequent login attempt. | G9: P1 | H9: Password reset integration with auth flow. | I9: Yes

Sheet Coverage Matrix
A1: TEST COVERAGE MATRIX All Three Screens
A2: Functional area coverage mapped to test case counts per screen
A3: Coverage Area | B3: Login Screen (LGN) | C3: OTP Screen (OTP) | D3: Dashboard (DSH) | E3: Integration (E2E) | F3: Total Tests | G3: Notes
A4: Happy Path / Positive Flows | B4: 3 | C4: 2 | D4: 1 | E4: 1 | F4: =B4+C4+D4+E4 -> 7 | G4: Core successful journeys
A5: Authentication & Session Handling | B5: 4 | C5: 2 | D5: 3 | E5: 3 | F5: =B5+C5+D5+E5 -> 12 | G5: Login, OTP, remember me, expiry, re-auth
A6: Form Validation — Client Side | B6: 3 | C6: 3 | D6: 0 | E6: 0 | F6: =B6+C6+D6+E6 -> 6 | G6: Empty fields, format, length checks
A7: Negative / Error Flows | B7: 3 | C7: 2 | D7: 0 | E7: 0 | F7: =B7+C7+D7+E7 -> 5 | G7: Wrong creds, wrong OTP, API errors
A8: OTP Lifecycle | B8: 0 | C8: 8 | D8: 0 | E8: 0 | F8: =B8+C8+D8+E8 -> 8 | G8: Generation, expiry, resend, single-use
A9: Widget Data & Filtering | B9: 0 | C9: 0 | D9: 15 | E9: 0 | F9: =B9+C9+D9+E9 -> 15 | G9: All 5 dashboard widgets, tabs, dropdowns
A10: Navigation & Routing | B10: 2 | C10: 2 | D10: 8 | E10: 0 | F10: =B10+C10+D10+E10 -> 12 | G10: Links, CTAs, sidebar, redirect handling
A11: Security Checks | B11: 7 | C11: 4 | D11: 3 | E11: 1 | F11: =B11+C11+D11+E11 -> 15 | G11: Injection, CSRF, HTTPS, RBAC, token storage
A12: Accessibility (WCAG 2.1 AA) | B12: 5 | C12: 4 | D12: 3 | E12: 0 | F12: =B12+C12+D12+E12 -> 12 | G12: Tab order, ARIA, SR labels, contrast
A13: Performance & Load | B13: 2 | C13: 1 | D13: 3 | E13: 0 | F13: =B13+C13+D13+E13 -> 6 | G13: LCP, CLS, skeleton loaders, throttled network
A14: Error Handling & Resilience | B14: 3 | C14: 3 | D14: 4 | E14: 0 | F14: =B14+C14+D14+E14 -> 10 | G14: 500 errors, timeouts, widget isolation
A15: Localisation / i18n | B15: 1 | C15: 0 | D15: 0 | E15: 0 | F15: =B15+C15+D15+E15 -> 1 | G15: Unicode, whitespace, placeholder text
... A19: UX / Visual | B19: 1 | C19: 2 | D19: 3 | E19: 0 | F19: =B19+C19+D19+E19 -> 6 | G19: Loading states, colour coding, paste, clipboard
A20: TOTALS | B20: =SUM(B4:B19) -> 0 | C20: =SUM(C4:C19) -> 0 | D20: =SUM(D4:D19) -> 0 | E20: =SUM(E4:E19) -> 0 | F20: =SUM(F4:F19) -> 128 | G20: 118 total test cases

Sheet Risk Register
A1: RISK REGISTER (Top 5 Risks Per Screen)
A2: Impact: Critical / High / Medium / Low | Likelihood: High / Medium / Low
A3: # | B3: Screen | C3: Risk Description | D3: Impact | E3: Likelihood | F3: Risk Score | G3: Mitigation Strategy
A4: 1 | B4: Login | C4: Credential brute-force attack on /login API endpoint | D4: Critical | E4: High | F4: CRITICAL | G4: Implement rate limiting (429 after 5 failures), exponential backoff, account lockout with email unlock, CAPTCHA on repeated failures.
A5: 2 | B5: Login | C5: Open-redirect via ?redirect param → phishing | D5: High | E5: Medium | F5: HIGH | G5: Whitelist allowed redirect paths server-side. Reject absolute URLs and external domains. Return 400 on invalid redirect.
A6: 3 | B6: Login | C6: Session cookie misconfiguration (missing HttpOnly/Secure/SameSite) | D6: High | E6: Medium | F6: HIGH | G6: Audit all Set-Cookie headers. Enforce HttpOnly, Secure, SameSite=Strict on auth cookies. Add to pre-release checklist.
A7: 4 | B7: Login | C7: Password field content exposure via clipboard logging or analytics events | D7: Low | E7: Low | F7: LOW | G7: Ensure type=password default. Never log field values in analytics/telemetry. Review third-party analytics scripts.
A8: 5 | B8: Login | C8: Remember Me creates long-lived token without rotation | D8: Medium | E8: Medium | F8: MEDIUM | G8: Rotate refresh tokens on each use. Set max 30-day expiry. Provide 'Sign out all devices' functionality.
A9: 6 | B9: OTP | C9: Brute-force OTP — 4 digits = only 10,000 combinations | D9: Critical | E9: High | F9: CRITICAL | G9: Rate-limit verify attempts per session/IP (max 5). Lock account after N failures. Consider 6-digit OTP for higher security.
A10: 7 | B10: OTP | C10: OTP replay attack — reusing already-verified OTP | D10: Critical | E10: Medium | F10: CRITICAL | G10: Mark OTP as used server-side immediately upon first successful verify. Reject used tokens. Enforce one-time use.
A11: 8 | B11: OTP | C11: OTP screen accessible without completing login step (auth bypass) | D11: Critical | E11: Medium | F11: CRITICAL | G11: Server validates intermediate session token on /verify endpoint. Direct /otp access without token returns 401.
A12: 9 | B12: OTP | C12: Email delivery failure — user cannot receive OTP | D12: High | E12: Medium | F12: HIGH | G12: Provide immediate resend after 60 s. Implement email delivery monitoring/alerting. Consider SMS fallback channel.
A13: 10 | B13: OTP | C13: Timer desync — OTP rejected prematurely due to client/server clock drift | D13: Medium | E13: Low | F13: MEDIUM | G13: Use server-side expiry check as authoritative. Client timer is UX-only. Add small grace period (e.g., 30 s) server-side.
A14: 11 | B14: Dashboard | C14: Insecure Direct Object Reference — manager sees out-of-scope data | D14: Critical | E14: Medium | F14: CRITICAL | G14: Backend enforces row-level security per manager scope. Test with multiple accounts having different region/site assignments.
... A18: 15 | B18: Dashboard | C18: Performance degradation with large data sets (100+ regions, 1000+ employees) | D18: Medium | E18: Medium | F18: MEDIUM | G18: Load test APIs with realistic data volumes. Implement pagination or virtual scrolling on Compliance table. Set widget data result caps.
